<?xml version="1.0" ?>
<robot name="BlueROV2 Heavy">
  <joint name="BlueROV2 Heavy__pressure_sensor_joint" type="fixed">
    <parent link="BlueROV2 Heavy__base_link"/>
    <child link="BlueROV2 Heavy__pressure_sensor_link"/>
    <origin xyz="0 0 0" rpy="0 0 0"/>
    <axis xyz="0 0 1"/>
    <limit lower="0.0" upper="0.0" effort="0.0" velocity="0.0"/>
  </joint>
  <joint name="BlueROV2 Heavy__range_sensor_joint" type="fixed">
    <parent link="BlueROV2 Heavy__base_link"/>
    <child link="BlueROV2 Heavy__range_sensor_link"/>
    <origin xyz="0.2 0  0.1" rpy="0 0 0"/>
    <axis xyz="0 0 1"/>
    <limit lower="0.0" upper="0.0" effort="0.0" velocity="0.0"/>
  </joint>
  <joint name="BlueROV2 Heavy__front_laser_joint" type="fixed">
    <parent link="BlueROV2 Heavy__base_link"/>
    <child link="BlueROV2 Heavy__front_laser_link"/>
    <origin xyz="0 0 0" rpy="0 0 0"/>
    <axis xyz="0 0 0"/>
    <limit lower="0" upper="0" effort="0" velocity="0"/>
  </joint>
  <joint name="BlueROV2 Heavy__velodyne_joint" type="fixed">
    <parent link="BlueROV2 Heavy__base_link"/>
    <child link="BlueROV2 Heavy__base_footprint"/>
    <origin xyz="0 0 0" rpy="0 0 0"/>
    <axis xyz="0 0 0"/>
    <limit lower="0" upper="0" effort="0" velocity="0"/>
  </joint>
  <joint name="BlueROV2 Heavy__thruster1_joint" type="revolute">
    <parent link="BlueROV2 Heavy__base_link"/>
    <child link="BlueROV2 Heavy__thruster1"/>
    <origin xyz="0.14 -0.1   0" rpy="0      1.57079 0.78539"/>
    <axis xyz="0 0 1"/>
    <limit lower="-1e+16" upper="1e+16" effort="0.0" velocity="0.0"/>
  </joint>
  <joint name="BlueROV2 Heavy__thruster2_joint" type="revolute">
    <parent link="BlueROV2 Heavy__base_link"/>
    <child link="BlueROV2 Heavy__thruster2"/>
    <origin xyz="0.14 0.1  0" rpy="0       1.57079 -0.78539"/>
    <axis xyz="0 0 1"/>
    <limit lower="-1e+16" upper="1e+16" effort="0.0" velocity="0.0"/>
  </joint>
  <joint name="BlueROV2 Heavy__thruster3_joint" type="revolute">
    <parent link="BlueROV2 Heavy__base_link"/>
    <child link="BlueROV2 Heavy__thruster3"/>
    <origin xyz="-0.14 -0.1   0" rpy="0      1.57079 2.35619"/>
    <axis xyz="0 0 1"/>
    <limit lower="-1e+16" upper="1e+16" effort="0.0" velocity="0.0"/>
  </joint>
  <joint name="BlueROV2 Heavy__thruster4_joint" type="revolute">
    <parent link="BlueROV2 Heavy__base_link"/>
    <child link="BlueROV2 Heavy__thruster4"/>
    <origin xyz="-0.14  0.1   0" rpy="0       1.57079 -2.35619"/>
    <axis xyz="0 0 1"/>
    <limit lower="-1e+16" upper="1e+16" effort="0.0" velocity="0.0"/>
  </joint>
  <joint name="BlueROV2 Heavy__thruster5_joint" type="revolute">
    <parent link="BlueROV2 Heavy__base_link"/>
    <child link="BlueROV2 Heavy__thruster5"/>
    <origin xyz="0.12 -0.22  0.06" rpy="0 0 0"/>
    <axis xyz="0 0 1"/>
    <limit lower="-1e+16" upper="1e+16" effort="0.0" velocity="0.0"/>
  </joint>
  <joint name="BlueROV2 Heavy__thruster6_joint" type="revolute">
    <parent link="BlueROV2 Heavy__base_link"/>
    <child link="BlueROV2 Heavy__thruster6"/>
    <origin xyz="0.12 0.22 0.06" rpy="0 0 0"/>
    <axis xyz="0 0 1"/>
    <limit lower="-1e+16" upper="1e+16" effort="0.0" velocity="0.0"/>
  </joint>
  <joint name="BlueROV2 Heavy__thruster7_joint" type="revolute">
    <parent link="BlueROV2 Heavy__base_link"/>
    <child link="BlueROV2 Heavy__thruster7"/>
    <origin xyz="-0.12 -0.22  0.06" rpy="0 0 0"/>
    <axis xyz="0 0 1"/>
    <limit lower="-1e+16" upper="1e+16" effort="0.0" velocity="0.0"/>
  </joint>
  <joint name="BlueROV2 Heavy__thruster8_joint" type="revolute">
    <parent link="BlueROV2 Heavy__base_link"/>
    <child link="BlueROV2 Heavy__thruster8"/>
    <origin xyz="-0.12  0.22  0.06" rpy="0 0 0"/>
    <axis xyz="0 0 1"/>
    <limit lower="-1e+16" upper="1e+16" effort="0.0" velocity="0.0"/>
  </joint>
  <link name="BlueROV2 Heavy__base_link">
    <inertial>
      <mass value="11"/>
      <origin xyz="0 0 0" rpy="0 0 0"/>
      <inertia ixx="0.1" ixy="0" ixz="0" iyy="0.1" iyz="0" izz="0.1"/>
    </inertial>
    <visual name="BlueROV2 Heavy__base_link_visual">
      <origin xyz="0 0 0" rpy="0 0 0"/>
      <geometry>
        <mesh filename="package://bluerov_sim/models/uuv_bluerov2_heavy/meshes/BlueROV2heavy.dae OR bluerov_sim/models/uuv_bluerov2_heavy_cam/meshes/BlueROV2heavy.dae OR pysdf/scripts/meshes/BlueROV2heavy.dae" scale="1.0 1.0 1.0"/>
      </geometry>
    </visual>
  </link>
  <link name="BlueROV2 Heavy__pressure_sensor_link">
    <inertial>
      <mass value="0.001"/>
      <origin xyz="0 0 0" rpy="0 0 0"/>
      <inertia ixx="1.0e-8" ixy="0" ixz="0" iyy="1.0e-8" iyz="0" izz="1.0e-8"/>
    </inertial>
  </link>
  <link name="BlueROV2 Heavy__range_sensor_link">
    <inertial>
      <mass value="0.001"/>
      <origin xyz="0 0 0" rpy="0 0 0"/>
      <inertia ixx="1.0e-8" ixy="0" ixz="0" iyy="1.0e-8" iyz="0" izz="1.0e-8"/>
    </inertial>
  </link>
  <link name="BlueROV2 Heavy__front_laser_link">
    <inertial>
      <mass value="0.001"/>
      <origin xyz="0 0 0" rpy="0 0 0"/>
      <inertia ixx="1.0e-8" ixy="0" ixz="0" iyy="1.0e-8" iyz="0" izz="1.0e-8"/>
    </inertial>
    <visual name="BlueROV2 Heavy__front_laser_visual">
      <origin xyz="0 0 0" rpy="0 0 0"/>
      <geometry>
        <mesh filename="package://bluerov_sim/models/uuv_bluerov2_heavy/meshes/laser/hokuyo.dae OR pysdf/scripts/meshes/laser/hokuyo.dae" scale="1 1 1"/>
      </geometry>
    </visual>
  </link>
  <link name="BlueROV2 Heavy__base_footprint">
    <inertial>
      <mass value="0.001"/>
      <origin xyz="0 0 0" rpy="0 0 0"/>
      <inertia ixx="1.0e-8" ixy="0" ixz="0" iyy="1.0e-8" iyz="0" izz="1.0e-8"/>
    </inertial>
    <collision name="BlueROV2 Heavy__base_footprint_collision_1">
      <origin xyz="0       0      -0.00185" rpy="0 0 0"/>
      <geometry>
        <cylinder radius="0.0516" length="0.0717"/>
      </geometry>
    </collision>
    <visual name="BlueROV2 Heavy__base_footprint_visual_1">
      <origin xyz="0       0      -0.03769" rpy="0 0 0"/>
      <geometry>
        <mesh filename="package://bluerov_sim/models/uuv_bluerov2_heavy/meshes/VLP16_base_1.dae OR pysdf/scripts/meshes/VLP16_base_1.dae" scale="1 1 1"/>
      </geometry>
    </visual>
    <visual name="BlueROV2 Heavy__base_footprint_visual_2">
      <origin xyz="0       0      -0.03769" rpy="0 0 0"/>
      <geometry>
        <mesh filename="package://bluerov_sim/models/uuv_bluerov2_heavy/meshes/VLP16_base_2.dae OR pysdf/scripts/meshes/VLP16_base_2.dae" scale="1 1 1"/>
      </geometry>
    </visual>
    <visual name="BlueROV2 Heavy__base_footprint_visual_3">
      <origin xyz="0       0      -0.03769" rpy="0 0 0"/>
      <geometry>
        <mesh filename="package://bluerov_sim/models/uuv_bluerov2_heavy/meshes/VLP16_scan.dae OR pysdf/scripts/meshes/VLP16_scan.dae" scale="1 1 1"/>
      </geometry>
    </visual>
  </link>
  <link name="BlueROV2 Heavy__thruster1">
    <inertial>
      <mass value="1e-10"/>
      <origin xyz="0 0 0" rpy="0 0 0"/>
      <inertia ixx="1e-06" ixy="0" ixz="0" iyy="1e-06" iyz="0" izz="1e-06"/>
    </inertial>
    <visual name="BlueROV2 Heavy__thruster1_visual">
      <origin xyz="0 0 0" rpy="0 0 0"/>
      <geometry>
        <mesh filename="package://bluerov_sim/models/uuv_bluerov2_heavy/meshes/prop.dae OR bluerov_sim/models/uuv_bluerov2_heavy_cam/meshes/prop.dae OR pysdf/scripts/meshes/prop.dae" scale="1 1 1"/>
      </geometry>
    </visual>
  </link>
  <link name="BlueROV2 Heavy__thruster2">
    <inertial>
      <mass value="1e-10"/>
      <origin xyz="0 0 0" rpy="0 0 0"/>
      <inertia ixx="1e-06" ixy="0" ixz="0" iyy="1e-06" iyz="0" izz="1e-06"/>
    </inertial>
    <visual name="BlueROV2 Heavy__thruster2_visual">
      <origin xyz="0 0 0" rpy="0 0 0"/>
      <geometry>
        <mesh filename="package://bluerov_sim/models/uuv_bluerov2_heavy/meshes/prop.dae OR bluerov_sim/models/uuv_bluerov2_heavy_cam/meshes/prop.dae OR pysdf/scripts/meshes/prop.dae" scale="1 1 1"/>
      </geometry>
    </visual>
  </link>
  <link name="BlueROV2 Heavy__thruster3">
    <inertial>
      <mass value="1e-10"/>
      <origin xyz="0 0 0" rpy="0 0 0"/>
      <inertia ixx="1e-06" ixy="0" ixz="0" iyy="1e-06" iyz="0" izz="1e-06"/>
    </inertial>
    <visual name="BlueROV2 Heavy__thruster3_visual">
      <origin xyz="0 0 0" rpy="0 0 0"/>
      <geometry>
        <mesh filename="package://bluerov_sim/models/uuv_bluerov2_heavy/meshes/prop.dae OR bluerov_sim/models/uuv_bluerov2_heavy_cam/meshes/prop.dae OR pysdf/scripts/meshes/prop.dae" scale="1 1 1"/>
      </geometry>
    </visual>
  </link>
  <link name="BlueROV2 Heavy__thruster4">
    <inertial>
      <mass value="1e-10"/>
      <origin xyz="0 0 0" rpy="0 0 0"/>
      <inertia ixx="1e-06" ixy="0" ixz="0" iyy="1e-06" iyz="0" izz="1e-06"/>
    </inertial>
    <visual name="BlueROV2 Heavy__thruster4_visual">
      <origin xyz="0 0 0" rpy="0 0 0"/>
      <geometry>
        <mesh filename="package://bluerov_sim/models/uuv_bluerov2_heavy/meshes/prop.dae OR bluerov_sim/models/uuv_bluerov2_heavy_cam/meshes/prop.dae OR pysdf/scripts/meshes/prop.dae" scale="1 1 1"/>
      </geometry>
    </visual>
  </link>
  <link name="BlueROV2 Heavy__thruster5">
    <inertial>
      <mass value="1e-10"/>
      <origin xyz="0 0 0" rpy="0 0 0"/>
      <inertia ixx="1e-06" ixy="0" ixz="0" iyy="1e-06" iyz="0" izz="1e-06"/>
    </inertial>
    <visual name="BlueROV2 Heavy__thruster5_visual">
      <origin xyz="0 0 0" rpy="0 0 0"/>
      <geometry>
        <mesh filename="package://bluerov_sim/models/uuv_bluerov2_heavy/meshes/prop.dae OR bluerov_sim/models/uuv_bluerov2_heavy_cam/meshes/prop.dae OR pysdf/scripts/meshes/prop.dae" scale="1 1 1"/>
      </geometry>
    </visual>
  </link>
  <link name="BlueROV2 Heavy__thruster6">
    <inertial>
      <mass value="1e-10"/>
      <origin xyz="0 0 0" rpy="0 0 0"/>
      <inertia ixx="1e-06" ixy="0" ixz="0" iyy="1e-06" iyz="0" izz="1e-06"/>
    </inertial>
    <visual name="BlueROV2 Heavy__thruster6_visual">
      <origin xyz="0 0 0" rpy="0 0 0"/>
      <geometry>
        <mesh filename="package://bluerov_sim/models/uuv_bluerov2_heavy/meshes/prop.dae OR bluerov_sim/models/uuv_bluerov2_heavy_cam/meshes/prop.dae OR pysdf/scripts/meshes/prop.dae" scale="1 1 1"/>
      </geometry>
    </visual>
  </link>
  <link name="BlueROV2 Heavy__thruster7">
    <inertial>
      <mass value="1e-10"/>
      <origin xyz="0 0 0" rpy="0 0 0"/>
      <inertia ixx="1e-06" ixy="0" ixz="0" iyy="1e-06" iyz="0" izz="1e-06"/>
    </inertial>
    <visual name="BlueROV2 Heavy__thruster7_visual">
      <origin xyz="0 0 0" rpy="0 0 0"/>
      <geometry>
        <mesh filename="package://bluerov_sim/models/uuv_bluerov2_heavy/meshes/prop.dae OR bluerov_sim/models/uuv_bluerov2_heavy_cam/meshes/prop.dae OR pysdf/scripts/meshes/prop.dae" scale="1 1 1"/>
      </geometry>
    </visual>
  </link>
  <link name="BlueROV2 Heavy__thruster8">
    <inertial>
      <mass value="1e-10"/>
      <origin xyz="0 0 0" rpy="0 0 0"/>
      <inertia ixx="1e-06" ixy="0" ixz="0" iyy="1e-06" iyz="0" izz="1e-06"/>
    </inertial>
    <visual name="BlueROV2 Heavy__thruster8_visual">
      <origin xyz="0 0 0" rpy="0 0 0"/>
      <geometry>
        <mesh filename="package://bluerov_sim/models/uuv_bluerov2_heavy/meshes/prop.dae OR bluerov_sim/models/uuv_bluerov2_heavy_cam/meshes/prop.dae OR pysdf/scripts/meshes/prop.dae" scale="1 1 1"/>
      </geometry>
    </visual>
  </link>
</robot>
